Workbook

Sheet Portada
B2: PLANTILLA DE EVALUACIÓN DE SEGURIDAD INFORMÁTICA
B3: Modelos MAGERIT y OCTAVE
B4: Universidad Mariano Gálvez de Guatemala — Seguridad de Sistemas Informáticos
B6: Pestaña | C6: Contenido y uso
B7: Inventario_Activos | C7: Registrar los activos de Producción, Pruebas y Desarrollo (hardware, software, datos, RRHH). Completar solo las celdas en amarillo/azul; la Criticidad y Clasificación se calculan solas.
B8: Escalas | C8: Tablas de referencia para las fórmulas (probabilidad, impacto, niveles de riesgo). No modificar.
B9: Riesgos | C9: Registrar mínimo 10 riesgos por activo: Capa de Seguridad por Profundidad, Brecha, Amenaza, Probabilidad e Impacto. El Riesgo MAGERIT, Nivel MAGERIT, Riesgo OCTAVE y Nivel OCTAVE se calculan automáticamente.
B10: Matriz_Calor | C10: Matriz de calor generada automáticamente (Probabilidad x Impacto) a partir de la hoja Riesgos.
B11: Tratamiento | C11: Resumen de tratamiento y priorización por activo, calculado automáticamente desde la hoja Riesgos.
B13: Leyenda de colores
B14: Celda amarilla / texto azul | C14: Campo que el equipo debe llenar
B15: Celda blanca / texto negro | C15: Campo calculado automáticamente por fórmula. No escribir sobre estas celdas.

Sheet Inventario_Activos
A1: No | B1: Ambiente | C1: Tipo de Activo | D1: Nombre del Activo | E1: Responsable | F1: Valor (1-5) | G1: Impacto en el Negocio (1-5) | H1: Confidencialidad (1-5) | I1: Criticidad (calculado) | J1: Clasificación (calculado)
A2: 1 | B2: Producción | C2: Hardware | D2: Servidor de Base de Datos | E2: Danny | F2: 4 | G2: 5 | H2: 5 | I2: =ROUND(AVERAGE(F2:H2),0) -> 5 | J2: =INDEX(Escalas!$B$10:$B$13,MATCH(I2,Escalas!$A$10:$A$13,1)) -> Alta
A3: 2 | B3: Producción | C3: Software | D3: Sistema ERP / Facturación | E3: Javier | F3: 3 | G3: 3 | H3: 3 | I3: =ROUND(AVERAGE(F3:H3),0) -> 3 | J3: =INDEX(Escalas!$B$10:$B$13,MATCH(I3,Escalas!$A$10:$A$13,1)) -> Media
A4: 3 | B4: Producción | C4: Datos | D4: Datos de clientes | E4: Katherin | F4: 3 | G4: 3 | H4: 3 | I4: =ROUND(AVERAGE(F4:H4),0) -> 3 | J4: =INDEX(Escalas!$B$10:$B$13,MATCH(I4,Escalas!$A$10:$A$13,1)) -> Media
A5: 4 | B5: Producción | C5: Recursos Humanos | D5: Administrador de sistemas | E5: Josue | F5: 3 | G5: 3 | H5: 3 | I5: =ROUND(AVERAGE(F5:H5),0) -> 3 | J5: =INDEX(Escalas!$B$10:$B$13,MATCH(I5,Escalas!$A$10:$A$13,1)) -> Media
A6: 5 | B6: Producción | C6: Hardware | D6: Firewall / Router de borde | E6: Diancarlo | F6: 3 | G6: 3 | H6: 3 | I6: =ROUND(AVERAGE(F6:H6),0) -> 3 | J6: =INDEX(Escalas!$B$10:$B$13,MATCH(I6,Escalas!$A$10:$A$13,1)) -> Media
A7: 6 | B7: Pruebas | C7: Hardware | D7: Servidor de pruebas | E7: Danny | F7: 3 | G7: 3 | H7: 3 | I7: =ROUND(AVERAGE(F7:H7),0) -> 3 | J7: =INDEX(Escalas!$B$10:$B$13,MATCH(I7,Escalas!$A$10:$A$13,1)) -> Media
A8: 7 | B8: Pruebas | C8: Software | D8: Ambiente de staging web | E8: Javier | F8: 3 | G8: 3 | H8: 3 | I8: =ROUND(AVERAGE(F8:H8),0) -> 3 | J8: =INDEX(Escalas!$B$10:$B$13,MATCH(I8,Escalas!$A$10:$A$13,1)) -> Media
A9: 8 | B9: Pruebas | C9: Datos | D9: Datos de prueba anonimizados | E9: Katherin | F9: 3 | G9: 3 | H9: 3 | I9: =ROUND(AVERAGE(F9:H9),0) -> 3 | J9: =INDEX(Escalas!$B$10:$B$13,MATCH(I9,Escalas!$A$10:$A$13,1)) -> Media
A10: 9 | B10: Pruebas | C10: Recursos Humanos | D10: QA Tester | E10: Josue | F10: 3 | G10: 3 | H10: 3 | I10: =ROUND(AVERAGE(F10:H10),0) -> 3 | J10: =INDEX(Escalas!$B$10:$B$13,MATCH(I10,Escalas!$A$10:$A$13,1)) -> Media
A11: 10 | B11: Pruebas | C11: Software | D11: Herramienta de automatización de pruebas | E11: Diancarlo | F11: 3 | G11: 3 | H11: 3 | I11: =ROUND(AVERAGE(F11:H11),0) -> 3 | J11: =INDEX(Escalas!$B$10:$B$13,MATCH(I11,Escalas!$A$10:$A$13,1)) -> Media
A12: 11 | B12: Desarrollo | C12: Hardware | D12: Estación de trabajo del desarrollador | E12: Danny | F12: 3 | G12: 3 | H12: 3 | I12: =ROUND(AVERAGE(F12:H12),0) -> 3 | J12: =INDEX(Escalas!$B$10:$B$13,MATCH(I12,Escalas!$A$10:$A$13,1)) -> Media
A13: 12 | B13: Desarrollo | C13: Software | D13: Repositorio de código (Git) | E13: Javier | F13: 3 | G13: 3 | H13: 3 | I13: =ROUND(AVERAGE(F13:H13),0) -> 3 | J13: =INDEX(Escalas!$B$10:$B$13,MATCH(I13,Escalas!$A$10:$A$13,1)) -> Media
... A16: 15 | B16: Desarrollo | C16: Software | D16: Entorno IDE / CI-CD | E16: Diancarlo | F16: 3 | G16: 3 | H16: 3 | I16: =ROUND(AVERAGE(F16:H16),0) -> 3 | J16: =INDEX(Escalas!$B$10:$B$13,MATCH(I16,Escalas!$A$10:$A$13,1)) -> Media
B18: Nota: Valor, Impacto en el Negocio y Confidencialidad se califican de 1 (muy bajo) a 5 (muy alto). La Criticidad es el promedio redondeado de esas 3 columnas.

Sheet Riesgos
A1: No | B1: Ambiente | C1: Tipo de Activo | D1: Activo | E1: Capa de Seguridad por Profundidad | F1: Brecha | G1: Amenaza | H1: Probabilidad (1-5) | I1: Impacto (1-5) | J1: Riesgo MAGERIT | K1: Nivel MAGERIT | L1: Criticidad del Activo | M1: Riesgo OCTAVE | N1: Nivel OCTAVE | O1: Tratamiento | P1: Solución / Control propuesto | Q1: Clave_Rank (auxiliar, no borrar)
A2: 1 | B2: =Inventario_Activos!B2 -> Producción | C2: =Inventario_Activos!C2 -> Hardware | D2: =Inventario_Activos!D2 -> Servidor de Base de Datos | E2: Seguridad Física | F2: Acceso no autorizado al cuarto de servidores | G2: Robo o sabotaje de hardware | H2: 2 | I2: 5 | J2: =H2*I2 -> 10 | K2: =INDEX(Escalas!$F$2:$F$5,MATCH(J2,Escalas!$E$2:$E$5,1)) -> Moderado | L2: =INDEX(Inventario_Activos!$I$2:$I$16,MATCH(D2,Inventario_Activos!$D$2:$D$16,0)) -> 5 | M2: =ROUND(J2*L2/5,0) -> 10 | N2: =INDEX(Escalas!$F$2:$F$5,MATCH(M2,Escalas!$E$2:$E$5,1)) -> Moderado | O2: Reducir/Mitigar | P2: Control de acceso biométrico y CCTV en el cuarto de servidores, con bitácora de ingreso. | Q2: =J2+(152-ROW())/100000 -> 10.0015
A3: 2 | B3: =Inventario_Activos!B2 -> Producción | C3: =Inventario_Activos!C2 -> Hardware | D3: =Inventario_Activos!D2 -> Servidor de Base de Datos | E3: Seguridad de Red | F3: Puertos de administración expuestos a la red interna | G3: Acceso remoto no autorizado | H3: 3 | I3: 5 | J3: =H3*I3 -> 15 | K3: =INDEX(Escalas!$F$2:$F$5,MATCH(J3,Escalas!$E$2:$E$5,1)) -> Alto | L3: =INDEX(Inventario_Activos!$I$2:$I$16,MATCH(D3,Inventario_Activos!$D$2:$D$16,0)) -> 5 | M3: =ROUND(J3*L3/5,0) -> 15 | N3: =INDEX(Escalas!$F$2:$F$5,MATCH(M3,Escalas!$E$2:$E$5,1)) -> Alto | O3: Reducir/Mitigar | P3: Segmentar la red de administración (VLAN dedicada) y exigir VPN + MFA para acceso remoto. | Q3: =J3+(152-ROW())/100000 -> 15.00149
A4: 3 | B4: =Inventario_Activos!B2 -> Producción | C4: =Inventario_Activos!C2 -> Hardware | D4: =Inventario_Activos!D2 -> Servidor de Base de Datos | E4: Seguridad de Host | F4: Sistema operativo del servidor desactualizado | G4: Explotación de vulnerabilidades conocidas | H4: 4 | I4: 4 | J4: =H4*I4 -> 16 | K4: =INDEX(Escalas!$F$2:$F$5,MATCH(J4,Escalas!$E$2:$E$5,1)) -> Alto | L4: =INDEX(Inventario_Activos!$I$2:$I$16,MATCH(D4,Inventario_Activos!$D$2:$D$16,0)) -> 5 | M4: =ROUND(J4*L4/5,0) -> 16 | N4: =INDEX(Escalas!$F$2:$F$5,MATCH(M4,Escalas!$E$2:$E$5,1)) -> Alto | O4: Reducir/Mitigar | P4: Gestión de parches automatizada y hardening del sistema operativo del servidor. | Q4: =J4+(152-ROW())/100000 -> 16.00148
A5: 4 | B5: =Inventario_Activos!B2 -> Producción | C5: =Inventario_Activos!C2 -> Hardware | D5: =Inventario_Activos!D2 -> Servidor de Base de Datos | E5: Seguridad de Aplicación | F5: Motor de base de datos con configuración por defecto | G5: Inyección SQL / escalamiento de privilegios | H5: 3 | I5: 5 | J5: =H5*I5 -> 15 | K5: =INDEX(Escalas!$F$2:$F$5,MATCH(J5,Escalas!$E$2:$E$5,1)) -> Alto | L5: =INDEX(Inventario_Activos!$I$2:$I$16,MATCH(D5,Inventario_Activos!$D$2:$D$16,0)) -> 5 | M5: =ROUND(J5*L5/5,0) -> 15 | N5: =INDEX(Escalas!$F$2:$F$5,MATCH(M5,Escalas!$E$2:$E$5,1)) -> Alto | O5: Reducir/Mitigar | P5: Validación de entradas, consultas parametrizadas y bastionado del motor de base de datos. | Q5: =J5+(152-ROW())/100000 -> 15.00147
A6: 5 | B6: =Inventario_Activos!B2 -> Producción | C6: =Inventario_Activos!C2 -> Hardware | D6: =Inventario_Activos!D2 -> Servidor de Base de Datos | E6: Seguridad de Datos | F6: Ausencia de cifrado en datos en reposo | G6: Fuga de información confidencial | H6: 3 | I6: 5 | J6: =H6*I6 -> 15 | K6: =INDEX(Escalas!$F$2:$F$5,MATCH(J6,Escalas!$E$2:$E$5,1)) -> Alto | L6: =INDEX(Inventario_Activos!$I$2:$I$16,MATCH(D6,Inventario_Activos!$D$2:$D$16,0)) -> 5 | M6: =ROUND(J6*L6/5,0) -> 15 | N6: =INDEX(Escalas!$F$2:$F$5,MATCH(M6,Escalas!$E$2:$E$5,1)) -> Alto | O6: Reducir/Mitigar | P6: Cifrar los datos en reposo (TDE) y en tránsito (TLS). | Q6: =J6+(152-ROW())/100000 -> 15.00146
A7: 6 | B7: =Inventario_Activos!B2 -> Producción | C7: =Inventario_Activos!C2 -> Hardware | D7: =Inventario_Activos!D2 -> Servidor de Base de Datos | E7: Gestión de Identidad y Acceso | F7: Cuentas de administrador compartidas | G7: Uso indebido de credenciales privilegiadas | H7: 3 | I7: 4 | J7: =H7*I7 -> 12 | K7: =INDEX(Escalas!$F$2:$F$5,MATCH(J7,Escalas!$E$2:$E$5,1)) -> Alto | L7: =INDEX(Inventario_Activos!$I$2:$I$16,MATCH(D7,Inventario_Activos!$D$2:$D$16,0)) -> 5 | M7: =ROUND(J7*L7/5,0) -> 12 | N7: =INDEX(Escalas!$F$2:$F$5,MATCH(M7,Escalas!$E$2:$E$5,1)) -> Alto | O7: Reducir/Mitigar | P7: Cuentas nominales, mínimo privilegio y bóveda de contraseñas (PAM). | Q7: =J7+(152-ROW())/100000 -> 12.00145
A8: 7 | B8: =Inventario_Activos!B2 -> Producción | C8: =Inventario_Activos!C2 -> Hardware | D8: =Inventario_Activos!D2 -> Servidor de Base de Datos | E8: Monitoreo y Respuesta | F8: Falta de registro (logging) centralizado | G8: Detección tardía de incidentes | H8: 3 | I8: 3 | J8: =H8*I8 -> 9 | K8: =INDEX(Escalas!$F$2:$F$5,MATCH(J8,Escalas!$E$2:$E$5,1)) -> Moderado | L8: =INDEX(Inventario_Activos!$I$2:$I$16,MATCH(D8,Inventario_Activos!$D$2:$D$16,0)) -> 5 | M8: =ROUND(J8*L8/5,0) -> 9 | N8: =INDEX(Escalas!$F$2:$F$5,MATCH(M8,Escalas!$E$2:$E$5,1)) -> Moderado | O8: Reducir/Mitigar | P8: Centralizar logs en un SIEM con alertas en tiempo real. | Q8: =J8+(152-ROW())/100000 -> 9.00144
A9: 8 | B9: =Inventario_Activos!B2 -> Producción | C9: =Inventario_Activos!C2 -> Hardware | D9: =Inventario_Activos!D2 -> Servidor de Base de Datos | E9: Continuidad y Respaldo | F9: Respaldos no probados periódicamente | G9: Pérdida de datos ante fallo o ataque | H9: 2 | I9: 5 | J9: =H9*I9 -> 10 | K9: =INDEX(Escalas!$F$2:$F$5,MATCH(J9,Escalas!$E$2:$E$5,1)) -> Moderado | L9: =INDEX(Inventario_Activos!$I$2:$I$16,MATCH(D9,Inventario_Activos!$D$2:$D$16,0)) -> 5 | M9: =ROUND(J9*L9/5,0) -> 10 | N9: =INDEX(Escalas!$F$2:$F$5,MATCH(M9,Escalas!$E$2:$E$5,1)) -> Moderado | O9: Reducir/Mitigar | P9: Plan de respaldo 3-2-1 con pruebas periódicas de restauración. | Q9: =J9+(152-ROW())/100000 -> 10.00143
A10: 9 | B10: =Inventario_Activos!B2 -> Producción | C10: =Inventario_Activos!C2 -> Hardware | D10: =Inventario_Activos!D2 -> Servidor de Base de Datos | E10: Seguridad Perimetral | F10: Reglas de firewall obsoletas o permisivas | G10: Movimiento lateral de un atacante | H10: 3 | I10: 4 | J10: =H10*I10 -> 12 | K10: =INDEX(Escalas!$F$2:$F$5,MATCH(J10,Escalas!$E$2:$E$5,1)) -> Alto | L10: =INDEX(Inventario_Activos!$I$2:$I$16,MATCH(D10,Inventario_Activos!$D$2:$D$16,0)) -> 5 | M10: =ROUND(J10*L10/5,0) -> 12 | N10: =INDEX(Escalas!$F$2:$F$5,MATCH(M10,Escalas!$E$2:$E$5,1)) -> Alto | O10: Reducir/Mitigar | P10: Revisar y depurar reglas de firewall; segmentación/microsegmentación de red. | Q10: =J10+(152-ROW())/100000 -> 12.00142
A11: 10 | B11: =Inventario_Activos!B2 -> Producción | C11: =Inventario_Activos!C2 -> Hardware | D11: =Inventario_Activos!D2 -> Servidor de Base de Datos | E11: Concientización y Procesos | F11: Falta de procedimiento de gestión de parches | G11: Explotación de vulnerabilidades no corregidas | H11: 4 | I11: 4 | J11: =H11*I11 -> 16 | K11: =INDEX(Escalas!$F$2:$F$5,MATCH(J11,Escalas!$E$2:$E$5,1)) -> Alto | L11: =INDEX(Inventario_Activos!$I$2:$I$16,MATCH(D11,Inventario_Activos!$D$2:$D$16,0)) -> 5 | M11: =ROUND(J11*L11/5,0) -> 16 | N11: =INDEX(Escalas!$F$2:$F$5,MATCH(M11,Escalas!$E$2:$E$5,1)) -> Alto | O11: Reducir/Mitigar | P11: Proceso formal de gestión de parches con SLA de aplicación. | Q11: =J11+(152-ROW())/100000 -> 16.00141
A12: 11 | B12: =Inventario_Activos!B3 -> Producción | C12: =Inventario_Activos!C3 -> Software | D12: =Inventario_Activos!D3 -> Sistema ERP / Facturación | E12: Seguridad Física | F12: Servidores del ERP alojados sin control de acceso físico restringido | G12: Acceso físico no autorizado al hardware que aloja el ERP | H12: 2 | I12: 4 | J12: =H12*I12 -> 8 | K12: =INDEX(Escalas!$F$2:$F$5,MATCH(J12,Escalas!$E$2:$E$5,1)) -> Moderado | L12: =INDEX(Inventario_Activos!$I$2:$I$16,MATCH(D12,Inventario_Activos!$D$2:$D$16,0)) -> 3 | M12: =ROUND(J12*L12/5,0) -> 5 | N12: =INDEX(Escalas!$F$2:$F$5,MATCH(M12,Escalas!$E$2:$E$5,1)) -> Bajo | O12: Reducir/Mitigar | P12: Alojar el servidor en centro de datos con control de acceso y video vigilancia. | Q12: =J12+(152-ROW())/100000 -> 8.0014
A13: 12 | B13: =Inventario_Activos!B3 -> Producción | C13: =Inventario_Activos!C3 -> Software | D13: =Inventario_Activos!D3 -> Sistema ERP / Facturación | E13: Seguridad de Red | F13: Comunicación del ERP sin cifrado entre módulos | G13: Intercepción de tráfico (sniffing) | H13: 3 | I13: 4 | J13: =H13*I13 -> 12 | K13: =INDEX(Escalas!$F$2:$F$5,MATCH(J13,Escalas!$E$2:$E$5,1)) -> Alto | L13: =INDEX(Inventario_Activos!$I$2:$I$16,MATCH(D13,Inventario_Activos!$D$2:$D$16,0)) -> 3 | M13: =ROUND(J13*L13/5,0) -> 7 | N13: =INDEX(Escalas!$F$2:$F$5,MATCH(M13,Escalas!$E$2:$E$5,1)) -> Moderado | O13: Reducir/Mitigar | P13: Cifrar comunicaciones internas con TLS y segmentar la red del ERP. | Q13: =J13+(152-ROW())/100000 -> 12.00139
A14: 13 | B14: =Inventario_Activos!B3 -> Producción | C14: =Inventario_Activos!C3 -> Software | D14: =Inventario_Activos!D3 -> Sistema ERP / Facturación | E14: Seguridad de Host | F14: Servidor de aplicaciones del ERP sin actualizaciones de seguridad | G14: Explotación de vulnerabilidades del sistema operativo | H14: 3 | I14: 4 | J14: =H14*I14 -> 12 | K14: =INDEX(Escalas!$F$2:$F$5,MATCH(J14,Escalas!$E$2:$E$5,1)) -> Alto | L14: =INDEX(Inventario_Activos!$I$2:$I$16,MATCH(D14,Inventario_Activos!$D$2:$D$16,0)) -> 3 | M14: =ROUND(J14*L14/5,0) -> 7 | N14: =INDEX(Escalas!$F$2:$F$5,MATCH(M14,Escalas!$E$2:$E$5,1)) -> Moderado | O14: Reducir/Mitigar | P14: Ciclo de actualización mensual y bastionado del servidor. | Q14: =J14+(152-ROW())/100000 -> 12.00138
A15: 14 | B15: =Inventario_Activos!B3 -> Producción | C15: =Inventario_Activos!C3 -> Software | D15: =Inventario_Activos!D3 -> Sistema ERP / Facturación | E15: Seguridad de Aplicación | F15: Módulo de facturación sin validación de entradas | G15: Inyección de código / manipulación de transacciones | H15: 3 | I15: 5 | J15: =H15*I15 -> 15 | K15: =INDEX(Escalas!$F$2:$F$5,MATCH(J15,Escalas!$E$2:$E$5,1)) -> Alto | L15: =INDEX(Inventario_Activos!$I$2:$I$16,MATCH(D15,Inventario_Activos!$D$2:$D$16,0)) -> 3 | M15: =ROUND(J15*L15/5,0) -> 9 | N15: =INDEX(Escalas!$F$2:$F$5,MATCH(M15,Escalas!$E$2:$E$5,1)) -> Moderado | O15: Reducir/Mitigar | P15: Pruebas de seguridad de aplicaciones (SAST/DAST) antes de cada release. | Q15: =J15+(152-ROW())/100000 -> 15.00137
A16: 15 | B16: =Inventario_Activos!B3 -> Producción | C16: =Inventario_Activos!C3 -> Software | D16: =Inventario_Activos!D3 -> Sistema ERP / Facturación | E16: Seguridad de Datos | F16: Base de datos del ERP sin cifrado de campos sensibles (montos, NIT) | G16: Exposición de información financiera | H16: 2 | I16: 5 | J16: =H16*I16 -> 10 | K16: =INDEX(Escalas!$F$2:$F$5,MATCH(J16,Escalas!$E$2:$E$5,1)) -> Moderado | L16: =INDEX(Inventario_Activos!$I$2:$I$16,MATCH(D16,Inventario_Activos!$D$2:$D$16,0)) -> 3 | M16: =ROUND(J16*L16/5,0) -> 6 | N16: =INDEX(Escalas!$F$2:$F$5,MATCH(M16,Escalas!$E$2:$E$5,1)) -> Moderado | O16: Reducir/Mitigar | P16: Cifrar campos sensibles y enmascarar datos en reportes. | Q16: =J16+(152-ROW())/100000 -> 10.00136
A17: 16 | B17: =Inventario_Activos!B3 -> Producción | C17: =Inventario_Activos!C3 -> Software | D17: =Inventario_Activos!D3 -> Sistema ERP / Facturación | E17: Gestión de Identidad y Acceso | F17: Roles del ERP mal configurados (usuarios con permisos excesivos) | G17: Fraude interno o modificación indebida de facturas | H17: 3 | I17: 5 | J17: =H17*I17 -> 15 | K17: =INDEX(Escalas!$F$2:$F$5,MATCH(J17,Escalas!$E$2:$E$5,1)) -> Alto | L17: =INDEX(Inventario_Activos!$I$2:$I$16,MATCH(D17,Inventario_Activos!$D$2:$D$16,0)) -> 3 | M17: =ROUND(J17*L17/5,0) -> 9 | N17: =INDEX(Escalas!$F$2:$F$5,MATCH(M17,Escalas!$E$2:$E$5,1)) -> Moderado | O17: Reducir/Mitigar | P17: Revisión periódica de roles y segregación de funciones (SoD). | Q17: =J17+(152-ROW())/100000 -> 15.00135
A18: 17 | B18: =Inventario_Activos!B3 -> Producción | C18: =Inventario_Activos!C3 -> Software | D18: =Inventario_Activos!D3 -> Sistema ERP / Facturación | E18: Monitoreo y Respuesta | F18: Ausencia de alertas ante transacciones inusuales | G18: Fraude no detectado a tiempo | H18: 3 | I18: 4 | J18: =H18*I18 -> 12 | K18: =INDEX(Escalas!$F$2:$F$5,MATCH(J18,Escalas!$E$2:$E$5,1)) -> Alto | L18: =INDEX(Inventario_Activos!$I$2:$I$16,MATCH(D18,Inventario_Activos!$D$2:$D$16,0)) -> 3 | M18: =ROUND(J18*L18/5,0) -> 7 | N18: =INDEX(Escalas!$F$2:$F$5,MATCH(M18,Escalas!$E$2:$E$5,1)) -> Moderado | O18: Reducir/Mitigar | P18: Reglas de auditoría y alertas de transacciones atípicas. | Q18: =J18+(152-ROW())/100000 -> 12.00134
A19: 18 | B19: =Inventario_Activos!B3 -> Producción | C19: =Inventario_Activos!C3 -> Software | D19: =Inventario_Activos!D3 -> Sistema ERP / Facturación | E19: Continuidad y Respaldo | F19: Backup del ERP solo en sitio, sin copia externa | G19: Pérdida de información contable ante desastre | H19: 2 | I19: 5 | J19: =H19*I19 -> 10 | K19: =INDEX(Escalas!$F$2:$F$5,MATCH(J19,Escalas!$E$2:$E$5,1)) -> Moderado | L19: =INDEX(Inventario_Activos!$I$2:$I$16,MATCH(D19,Inventario_Activos!$D$2:$D$16,0)) -> 3 | M19: =ROUND(J19*L19/5,0) -> 6 | N19: =INDEX(Escalas!$F$2:$F$5,MATCH(M19,Escalas!$E$2:$E$5,1)) -> Moderado | O19: Reducir/Mitigar | P19: Respaldo en la nube con retención definida y prueba de restauración. | Q19: =J19+(152-ROW())/100000 -> 10.00133
A20: 19 | B20: =Inventario_Activos!B3 -> Producción | C20: =Inventario_Activos!C3 -> Software | D20: =Inventario_Activos!D3 -> Sistema ERP / Facturación | E20: Seguridad Perimetral | F20: Puerto de administración del ERP expuesto a internet | G20: Acceso externo no autorizado a la consola de administración | H20: 3 | I20: 4 | J20: =H20*I20 -> 12 | K20: =INDEX(Escalas!$F$2:$F$5,MATCH(J20,Escalas!$E$2:$E$5,1)) -> Alto | L20: =INDEX(Inventario_Activos!$I$2:$I$16,MATCH(D20,Inventario_Activos!$D$2:$D$16,0)) -> 3 | M20: =ROUND(J20*L20/5,0) -> 7 | N20: =INDEX(Escalas!$F$2:$F$5,MATCH(M20,Escalas!$E$2:$E$5,1)) -> Moderado | O20: Reducir/Mitigar | P20: Restringir el acceso administrativo a IPs internas mediante firewall/VPN. | Q20: =J20+(152-ROW())/100000 -> 12.00132
A21: 20 | B21: =Inventario_Activos!B3 -> Producción | C21: =Inventario_Activos!C3 -> Software | D21: =Inventario_Activos!D3 -> Sistema ERP / Facturación | E21: Concientización y Procesos | F21: Falta de capacitación a usuarios sobre manejo del ERP | G21: Errores de captura y fraude por desconocimiento | H21: 3 | I21: 3 | J21: =H21*I21 -> 9 | K21: =INDEX(Escalas!$F$2:$F$5,MATCH(J21,Escalas!$E$2:$E$5,1)) -> Moderado | L21: =INDEX(Inventario_Activos!$I$2:$I$16,MATCH(D21,Inventario_Activos!$D$2:$D$16,0)) -> 3 | M21: =ROUND(J21*L21/5,0) -> 5 | N21: =INDEX(Escalas!$F$2:$F$5,MATCH(M21,Escalas!$E$2:$E$5,1)) -> Bajo | O21: Reducir/Mitigar | P21: Capacitación periódica y manual de procedimientos de uso. | Q21: =J21+(152-ROW())/100000 -> 9.00131
A22: 21 | B22: =Inventario_Activos!B4 -> Producción | C22: =Inventario_Activos!C4 -> Datos | D22: =Inventario_Activos!D4 -> Datos de clientes | E22: Seguridad Física | F22: Medios de respaldo con datos de clientes almacenados sin resguardo físico | G22: Robo o pérdida de medios de respaldo | H22: 2 | I22: 5 | J22: =H22*I22 -> 10 | K22: =INDEX(Escalas!$F$2:$F$5,MATCH(J22,Escalas!$E$2:$E$5,1)) -> Moderado | L22: =INDEX(Inventario_Activos!$I$2:$I$16,MATCH(D22,Inventario_Activos!$D$2:$D$16,0)) -> 3 | M22: =ROUND(J22*L22/5,0) -> 6 | N22: =INDEX(Escalas!$F$2:$F$5,MATCH(M22,Escalas!$E$2:$E$5,1)) -> Moderado | O22: Reducir/Mitigar | P22: Resguardo en caja fuerte o custodia externa certificada. | Q22: =J22+(152-ROW())/100000 -> 10.0013
A23: 22 | B23: =Inventario_Activos!B4 -> Producción | C23: =Inventario_Activos!C4 -> Datos | D23: =Inventario_Activos!D4 -> Datos de clientes | E23: Seguridad de Red | F23: Transferencia de datos de clientes entre sistemas sin cifrado | G23: Intercepción de información personal en tránsito | H23: 3 | I23: 5 | J23: =H23*I23 -> 15 | K23: =INDEX(Escalas!$F$2:$F$5,MATCH(J23,Escalas!$E$2:$E$5,1)) -> Alto | L23: =INDEX(Inventario_Activos!$I$2:$I$16,MATCH(D23,Inventario_Activos!$D$2:$D$16,0)) -> 3 | M23: =ROUND(J23*L23/5,0) -> 9 | N23: =INDEX(Escalas!$F$2:$F$5,MATCH(M23,Escalas!$E$2:$E$5,1)) -> Moderado | O23: Reducir/Mitigar | P23: Cifrado TLS obligatorio en todas las transferencias de datos. | Q23: =J23+(152-ROW())/100000 -> 15.00129
A24: 23 | B24: =Inventario_Activos!B4 -> Producción | C24: =Inventario_Activos!C4 -> Datos | D24: =Inventario_Activos!D4 -> Datos de clientes | E24: Seguridad de Host | F24: Base de datos de clientes en servidor sin bastionado específico | G24: Compromiso del servidor que aloja los datos | H24: 3 | I24: 5 | J24: =H24*I24 -> 15 | K24: =INDEX(Escalas!$F$2:$F$5,MATCH(J24,Escalas!$E$2:$E$5,1)) -> Alto | L24: =INDEX(Inventario_Activos!$I$2:$I$16,MATCH(D24,Inventario_Activos!$D$2:$D$16,0)) -> 3 | M24: =ROUND(J24*L24/5,0) -> 9 | N24: =INDEX(Escalas!$F$2:$F$5,MATCH(M24,Escalas!$E$2:$E$5,1)) -> Moderado | O24: Reducir/Mitigar | P24: Hardening del servidor de base de datos y monitoreo de integridad. | Q24: =J24+(152-ROW())/100000 -> 15.00128
A25: 24 | B25: =Inventario_Activos!B4 -> Producción | C25: =Inventario_Activos!C4 -> Datos | D25: =Inventario_Activos!D4 -> Datos de clientes | E25: Seguridad de Aplicación | F25: Aplicaciones con acceso directo a la base de datos sin capa de control | G25: Exfiltración de datos mediante consultas no controladas | H25: 3 | I25: 5 | J25: =H25*I25 -> 15 | K25: =INDEX(Escalas!$F$2:$F$5,MATCH(J25,Escalas!$E$2:$E$5,1)) -> Alto | L25: =INDEX(Inventario_Activos!$I$2:$I$16,MATCH(D25,Inventario_Activos!$D$2:$D$16,0)) -> 3 | M25: =ROUND(J25*L25/5,0) -> 9 | N25: =INDEX(Escalas!$F$2:$F$5,MATCH(M25,Escalas!$E$2:$E$5,1)) -> Moderado | O25: Reducir/Mitigar | P25: Implementar capa de API con control de acceso y limitación de consultas. | Q25: =J25+(152-ROW())/100000 -> 15.00127
A26: 25 | B26: =Inventario_Activos!B4 -> Producción | C26: =Inventario_Activos!C4 -> Datos | D26: =Inventario_Activos!D4 -> Datos de clientes | E26: Seguridad de Datos | F26: Datos personales sin cifrado ni enmascaramiento | G26: Fuga de información personal (incumplimiento normativo) | H26: 3 | I26: 5 | J26: =H26*I26 -> 15 | K26: =INDEX(Escalas!$F$2:$F$5,MATCH(J26,Escalas!$E$2:$E$5,1)) -> Alto | L26: =INDEX(Inventario_Activos!$I$2:$I$16,MATCH(D26,Inventario_Activos!$D$2:$D$16,0)) -> 3 | M26: =ROUND(J26*L26/5,0) -> 9 | N26: =INDEX(Escalas!$F$2:$F$5,MATCH(M26,Escalas!$E$2:$E$5,1)) -> Moderado | O26: Reducir/Mitigar | P26: Cifrado de campos sensibles y clasificación de datos personales. | Q26: =J26+(152-ROW())/100000 -> 15.00126
A27: 26 | B27: =Inventario_Activos!B4 -> Producción | C27: =Inventario_Activos!C4 -> Datos | D27: =Inventario_Activos!D4 -> Datos de clientes | E27: Gestión de Identidad y Acceso | F27: Múltiples roles con acceso de lectura/escritura a todos los datos de clientes | G27: Acceso indebido o excesivo a información personal | H27: 3 | I27: 5 | J27: =H27*I27 -> 15 | K27: =INDEX(Escalas!$F$2:$F$5,MATCH(J27,Escalas!$E$2:$E$5,1)) -> Alto | L27: =INDEX(Inventario_Activos!$I$2:$I$16,MATCH(D27,Inventario_Activos!$D$2:$D$16,0)) -> 3 | M27: =ROUND(J27*L27/5,0) -> 9 | N27: =INDEX(Escalas!$F$2:$F$5,MATCH(M27,Escalas!$E$2:$E$5,1)) -> Moderado | O27: Reducir/Mitigar | P27: Control de acceso basado en roles con mínimo privilegio. | Q27: =J27+(152-ROW())/100000 -> 15.00125
A28: 27 | B28: =Inventario_Activos!B4 -> Producción | C28: =Inventario_Activos!C4 -> Datos | D28: =Inventario_Activos!D4 -> Datos de clientes | E28: Monitoreo y Respuesta | F28: Sin auditoría de consultas a datos sensibles de clientes | G28: Acceso indebido no detectado | H28: 3 | I28: 4 | J28: =H28*I28 -> 12 | K28: =INDEX(Escalas!$F$2:$F$5,MATCH(J28,Escalas!$E$2:$E$5,1)) -> Alto | L28: =INDEX(Inventario_Activos!$I$2:$I$16,MATCH(D28,Inventario_Activos!$D$2:$D$16,0)) -> 3 | M28: =ROUND(J28*L28/5,0) -> 7 | N28: =INDEX(Escalas!$F$2:$F$5,MATCH(M28,Escalas!$E$2:$E$5,1)) -> Moderado | O28: Reducir/Mitigar | P28: Auditoría de accesos a datos sensibles (Database Activity Monitoring). | Q28: =J28+(152-ROW())/100000 -> 12.00124
A29: 28 | B29: =Inventario_Activos!B4 -> Producción | C29: =Inventario_Activos!C4 -> Datos | D29: =Inventario_Activos!D4 -> Datos de clientes | E29: Continuidad y Respaldo | F29: Respaldos de datos de clientes sin cifrado | G29: Exposición de datos personales ante robo de respaldo | H29: 2 | I29: 5 | J29: =H29*I29 -> 10 | K29: =INDEX(Escalas!$F$2:$F$5,MATCH(J29,Escalas!$E$2:$E$5,1)) -> Moderado | L29: =INDEX(Inventario_Activos!$I$2:$I$16,MATCH(D29,Inventario_Activos!$D$2:$D$16,0)) -> 3 | M29: =ROUND(J29*L29/5,0) -> 6 | N29: =INDEX(Escalas!$F$2:$F$5,MATCH(M29,Escalas!$E$2:$E$5,1)) -> Moderado | O29: Reducir/Mitigar | P29: Cifrado de respaldos y control de acceso a los mismos. | Q29: =J29+(152-ROW())/100000 -> 10.00123
A30: 29 | B30: =Inventario_Activos!B4 -> Producción | C30: =Inventario_Activos!C4 -> Datos | D30: =Inventario_Activos!D4 -> Datos de clientes | E30: Seguridad Perimetral | F30: Exportaciones masivas de datos permitidas sin control | G30: Exfiltración masiva de datos de clientes | H30: 2 | I30: 5 | J30: =H30*I30 -> 10 | K30: =INDEX(Escalas!$F$2:$F$5,MATCH(J30,Escalas!$E$2:$E$5,1)) -> Moderado | L30: =INDEX(Inventario_Activos!$I$2:$I$16,MATCH(D30,Inventario_Activos!$D$2:$D$16,0)) -> 3 | M30: =ROUND(J30*L30/5,0) -> 6 | N30: =INDEX(Escalas!$F$2:$F$5,MATCH(M30,Escalas!$E$2:$E$5,1)) -> Moderado | O30: Reducir/Mitigar | P30: Limitar y auditar las exportaciones masivas de datos (DLP). | Q30: =J30+(152-ROW())/100000 -> 10.00122
A31: 30 | B31: =Inventario_Activos!B4 -> Producción | C31: =Inventario_Activos!C4 -> Datos | D31: =Inventario_Activos!D4 -> Datos de clientes | E31: Concientización y Procesos | F31: Falta de política de protección de datos personales | G31: Manejo inadecuado de datos por parte del personal | H31: 3 | I31: 4 | J31: =H31*I31 -> 12 | K31: =INDEX(Escalas!$F$2:$F$5,MATCH(J31,Escalas!$E$2:$E$5,1)) -> Alto | L31: =INDEX(Inventario_Activos!$I$2:$I$16,MATCH(D31,Inventario_Activos!$D$2:$D$16,0)) -> 3 | M31: =ROUND(J31*L31/5,0) -> 7 | N31: =INDEX(Escalas!$F$2:$F$5,MATCH(M31,Escalas!$E$2:$E$5,1)) -> Moderado | O31: Reducir/Mitigar | P31: Política de protección de datos y capacitación en normativa aplicable. | Q31: =J31+(152-ROW())/100000 -> 12.00121
A32: 31 | B32: =Inventario_Activos!B5 -> Producción | C32: =Inventario_Activos!C5 -> Recursos Humanos | D32: =Inventario_Activos!D5 -> Administrador de sistemas | E32: Seguridad Física | F32: Sin control de acceso a áreas críticas para el administrador de sistemas | G32: Ingreso no autorizado a zonas restringidas | H32: 2 | I32: 3 | J32: =H32*I32 -> 6 | K32: =INDEX(Escalas!$F$2:$F$5,MATCH(J32,Escalas!$E$2:$E$5,1)) -> Moderado | L32: =INDEX(Inventario_Activos!$I$2:$I$16,MATCH(D32,Inventario_Activos!$D$2:$D$16,0)) -> 3 | M32: =ROUND(J32*L32/5,0) -> 4 | N32: =INDEX(Escalas!$F$2:$F$5,MATCH(M32,Escalas!$E$2:$E$5,1)) -> Bajo | O32: Reducir/Mitigar | P32: Control de acceso físico basado en roles y bitácora de ingreso. | Q32: =J32+(152-ROW())/100000 -> 6.0012
A33: 32 | B33: =Inventario_Activos!B5 -> Producción | C33: =Inventario_Activos!C5 -> Recursos Humanos | D33: =Inventario_Activos!D5 -> Administrador de sistemas | E33: Seguridad de Red | F33: Acceso remoto del administrador sin restricciones ni VPN | G33: Interceptación de sesiones de administración remota | H33: 3 | I33: 5 | J33: =H33*I33 -> 15 | K33: =INDEX(Escalas!$F$2:$F$5,MATCH(J33,Escalas!$E$2:$E$5,1)) -> Alto | L33: =INDEX(Inventario_Activos!$I$2:$I$16,MATCH(D33,Inventario_Activos!$D$2:$D$16,0)) -> 3 | M33: =ROUND(J33*L33/5,0) -> 9 | N33: =INDEX(Escalas!$F$2:$F$5,MATCH(M33,Escalas!$E$2:$E$5,1)) -> Moderado | O33: Reducir/Mitigar | P33: Acceso remoto únicamente mediante VPN con MFA. | Q33: =J33+(152-ROW())/100000 -> 15.00119
A34: 33 | B34: =Inventario_Activos!B5 -> Producción | C34: =Inventario_Activos!C5 -> Recursos Humanos | D34: =Inventario_Activos!D5 -> Administrador de sistemas | E34: Seguridad de Host | F34: Estación del administrador sin controles reforzados pese a sus privilegios | G34: Compromiso del equipo usado para tareas administrativas | H34: 3 | I34: 5 | J34: =H34*I34 -> 15 | K34: =INDEX(Escalas!$F$2:$F$5,MATCH(J34,Escalas!$E$2:$E$5,1)) -> Alto | L34: =INDEX(Inventario_Activos!$I$2:$I$16,MATCH(D34,Inventario_Activos!$D$2:$D$16,0)) -> 3 | M34: =ROUND(J34*L34/5,0) -> 9 | N34: =INDEX(Escalas!$F$2:$F$5,MATCH(M34,Escalas!$E$2:$E$5,1)) -> Moderado | O34: Reducir/Mitigar | P34: Estación dedicada y reforzada (PAW) para tareas administrativas. | Q34: =J34+(152-ROW())/100000 -> 15.00118
A35: 34 | B35: =Inventario_Activos!B5 -> Producción | C35: =Inventario_Activos!C5 -> Recursos Humanos | D35: =Inventario_Activos!D5 -> Administrador de sistemas | E35: Seguridad de Aplicación | F35: Uso de una sola cuenta de administrador para múltiples sistemas | G35: Movimiento lateral en caso de compromiso de la cuenta | H35: 3 | I35: 5 | J35: =H35*I35 -> 15 | K35: =INDEX(Escalas!$F$2:$F$5,MATCH(J35,Escalas!$E$2:$E$5,1)) -> Alto | L35: =INDEX(Inventario_Activos!$I$2:$I$16,MATCH(D35,Inventario_Activos!$D$2:$D$16,0)) -> 3 | M35: =ROUND(J35*L35/5,0) -> 9 | N35: =INDEX(Escalas!$F$2:$F$5,MATCH(M35,Escalas!$E$2:$E$5,1)) -> Moderado | O35: Reducir/Mitigar | P35: Cuentas administrativas separadas por sistema y uso de PAM. | Q35: =J35+(152-ROW())/100000 -> 15.00117
A36: 35 | B36: =Inventario_Activos!B5 -> Producción | C36: =Inventario_Activos!C5 -> Recursos Humanos | D36: =Inventario_Activos!D5 -> Administrador de sistemas | E36: Seguridad de Datos | F36: Acceso amplio del administrador a todos los datos sin justificación operativa | G36: Abuso de privilegios para acceder a información sensible | H36: 2 | I36: 4 | J36: =H36*I36 -> 8 | K36: =INDEX(Escalas!$F$2:$F$5,MATCH(J36,Escalas!$E$2:$E$5,1)) -> Moderado | L36: =INDEX(Inventario_Activos!$I$2:$I$16,MATCH(D36,Inventario_Activos!$D$2:$D$16,0)) -> 3 | M36: =ROUND(J36*L36/5,0) -> 5 | N36: =INDEX(Escalas!$F$2:$F$5,MATCH(M36,Escalas!$E$2:$E$5,1)) -> Bajo | O36: Reducir/Mitigar | P36: Limitar el acceso a datos según necesidad y registrar accesos privilegiados. | Q36: =J36+(152-ROW())/100000 -> 8.00116
A37: 36 | B37: =Inventario_Activos!B5 -> Producción | C37: =Inventario_Activos!C5 -> Recursos Humanos | D37: =Inventario_Activos!D5 -> Administrador de sistemas | E37: Gestión de Identidad y Acceso | F37: Falta de revisión periódica de privilegios asignados al rol | G37: Acumulación de privilegios innecesarios (privilege creep) | H37: 3 | I37: 4 | J37: =H37*I37 -> 12 | K37: =INDEX(Escalas!$F$2:$F$5,MATCH(J37,Escalas!$E$2:$E$5,1)) -> Alto | L37: =INDEX(Inventario_Activos!$I$2:$I$16,MATCH(D37,Inventario_Activos!$D$2:$D$16,0)) -> 3 | M37: =ROUND(J37*L37/5,0) -> 7 | N37: =INDEX(Escalas!$F$2:$F$5,MATCH(M37,Escalas!$E$2:$E$5,1)) -> Moderado | O37: Reducir/Mitigar | P37: Revisión periódica de privilegios y certificación de accesos. | Q37: =J37+(152-ROW())/100000 -> 12.00115
A38: 37 | B38: =Inventario_Activos!B5 -> Producción | C38: =Inventario_Activos!C5 -> Recursos Humanos | D38: =Inventario_Activos!D5 -> Administrador de sistemas | E38: Monitoreo y Respuesta | F38: Actividades del administrador no auditadas de forma independiente | G38: Acciones maliciosas o erróneas sin detección (amenaza interna) | H38: 3 | I38: 5 | J38: =H38*I38 -> 15 | K38: =INDEX(Escalas!$F$2:$F$5,MATCH(J38,Escalas!$E$2:$E$5,1)) -> Alto | L38: =INDEX(Inventario_Activos!$I$2:$I$16,MATCH(D38,Inventario_Activos!$D$2:$D$16,0)) -> 3 | M38: =ROUND(J38*L38/5,0) -> 9 | N38: =INDEX(Escalas!$F$2:$F$5,MATCH(M38,Escalas!$E$2:$E$5,1)) -> Moderado | O38: Reducir/Mitigar | P38: Auditoría independiente y grabación de sesiones privilegiadas. | Q38: =J38+(152-ROW())/100000 -> 15.00114
A39: 38 | B39: =Inventario_Activos!B5 -> Producción | C39: =Inventario_Activos!C5 -> Recursos Humanos | D39: =Inventario_Activos!D5 -> Administrador de sistemas | E39: Continuidad y Respaldo | F39: Dependencia de una sola persona para tareas administrativas críticas | G39: Interrupción de operaciones ante ausencia del administrador | H39: 3 | I39: 4 | J39: =H39*I39 -> 12 | K39: =INDEX(Escalas!$F$2:$F$5,MATCH(J39,Escalas!$E$2:$E$5,1)) -> Alto | L39: =INDEX(Inventario_Activos!$I$2:$I$16,MATCH(D39,Inventario_Activos!$D$2:$D$16,0)) -> 3 | M39: =ROUND(J39*L39/5,0) -> 7 | N39: =INDEX(Escalas!$F$2:$F$5,MATCH(M39,Escalas!$E$2:$E$5,1)) -> Moderado | O39: Reducir/Mitigar | P39: Documentar procedimientos y contar con un administrador de respaldo. | Q39: =J39+(152-ROW())/100000 -> 12.00113
A40: 39 | B40: =Inventario_Activos!B5 -> Producción | C40: =Inventario_Activos!C5 -> Recursos Humanos | D40: =Inventario_Activos!D5 -> Administrador de sistemas | E40: Seguridad Perimetral | F40: Acceso administrativo posible desde cualquier ubicación sin restricción geográfica | G40: Acceso indebido desde ubicaciones no habituales | H40: 2 | I40: 4 | J40: =H40*I40 -> 8 | K40: =INDEX(Escalas!$F$2:$F$5,MATCH(J40,Escalas!$E$2:$E$5,1)) -> Moderado | L40: =INDEX(Inventario_Activos!$I$2:$I$16,MATCH(D40,Inventario_Activos!$D$2:$D$16,0)) -> 3 | M40: =ROUND(J40*L40/5,0) -> 5 | N40: =INDEX(Escalas!$F$2:$F$5,MATCH(M40,Escalas!$E$2:$E$5,1)) -> Bajo | O40: Reducir/Mitigar | P40: Restringir accesos administrativos por geolocalización/IP y alertar anomalías. | Q40: =J40+(152-ROW())/100000 -> 8.00112
...

Sheet Matriz_Calor
A1: Matriz de Calor — Frecuencia de Riesgos por Probabilidad x Impacto
A3: Probabilidad \ Impacto | B3: 1 | C3: 2 | D3: 3 | E3: 4 | F3: 5
A4: 1 | B4: =COUNTIFS(Riesgos!$H$2:$H$151,1,Riesgos!$I$2:$I$151,1) -> 0 | C4: =COUNTIFS(Riesgos!$H$2:$H$151,1,Riesgos!$I$2:$I$151,2) -> 0 | D4: =COUNTIFS(Riesgos!$H$2:$H$151,1,Riesgos!$I$2:$I$151,3) -> 0 | E4: =COUNTIFS(Riesgos!$H$2:$H$151,1,Riesgos!$I$2:$I$151,4) -> 0 | F4: =COUNTIFS(Riesgos!$H$2:$H$151,1,Riesgos!$I$2:$I$151,5) -> 0
A5: 2 | B5: =COUNTIFS(Riesgos!$H$2:$H$151,2,Riesgos!$I$2:$I$151,1) -> 0 | C5: =COUNTIFS(Riesgos!$H$2:$H$151,2,Riesgos!$I$2:$I$151,2) -> 7 | D5: =COUNTIFS(Riesgos!$H$2:$H$151,2,Riesgos!$I$2:$I$151,3) -> 12 | E5: =COUNTIFS(Riesgos!$H$2:$H$151,2,Riesgos!$I$2:$I$151,4) -> 11 | F5: =COUNTIFS(Riesgos!$H$2:$H$151,2,Riesgos!$I$2:$I$151,5) -> 9
A6: 3 | B6: =COUNTIFS(Riesgos!$H$2:$H$151,3,Riesgos!$I$2:$I$151,1) -> 0 | C6: =COUNTIFS(Riesgos!$H$2:$H$151,3,Riesgos!$I$2:$I$151,2) -> 3 | D6: =COUNTIFS(Riesgos!$H$2:$H$151,3,Riesgos!$I$2:$I$151,3) -> 32 | E6: =COUNTIFS(Riesgos!$H$2:$H$151,3,Riesgos!$I$2:$I$151,4) -> 43 | F6: =COUNTIFS(Riesgos!$H$2:$H$151,3,Riesgos!$I$2:$I$151,5) -> 26
A7: 4 | B7: =COUNTIFS(Riesgos!$H$2:$H$151,4,Riesgos!$I$2:$I$151,1) -> 0 | C7: =COUNTIFS(Riesgos!$H$2:$H$151,4,Riesgos!$I$2:$I$151,2) -> 0 | D7: =COUNTIFS(Riesgos!$H$2:$H$151,4,Riesgos!$I$2:$I$151,3) -> 0 | E7: =COUNTIFS(Riesgos!$H$2:$H$151,4,Riesgos!$I$2:$I$151,4) -> 6 | F7: =COUNTIFS(Riesgos!$H$2:$H$151,4,Riesgos!$I$2:$I$151,5) -> 1
A8: 5 | B8: =COUNTIFS(Riesgos!$H$2:$H$151,5,Riesgos!$I$2:$I$151,1) -> 0 | C8: =COUNTIFS(Riesgos!$H$2:$H$151,5,Riesgos!$I$2:$I$151,2) -> 0 | D8: =COUNTIFS(Riesgos!$H$2:$H$151,5,Riesgos!$I$2:$I$151,3) -> 0 | E8: =COUNTIFS(Riesgos!$H$2:$H$151,5,Riesgos!$I$2:$I$151,4) -> 0 | F8: =COUNTIFS(Riesgos!$H$2:$H$151,5,Riesgos!$I$2:$I$151,5) -> 0
A10: Total de riesgos registrados: | B10: =COUNTA(Riesgos!$A$2:$A$151) -> 150
A12: Resumen por Nivel MAGERIT | D12: Resumen por Nivel OCTAVE
A13: Nivel | B13: Cantidad de riesgos | D13: Nivel | E13: Cantidad de riesgos
A14: Bajo | B14: =COUNTIF(Riesgos!$K$2:$K$151,"Bajo") -> 7 | D14: Bajo | E14: =COUNTIF(Riesgos!$N$2:$N$151,"Bajo") -> 64
A15: Moderado | B15: =COUNTIF(Riesgos!$K$2:$K$151,"Moderado") -> 67 | D15: Moderado | E15: =COUNTIF(Riesgos!$N$2:$N$151,"Moderado") -> 78
A16: Alto | B16: =COUNTIF(Riesgos!$K$2:$K$151,"Alto") -> 76 | D16: Alto | E16: =COUNTIF(Riesgos!$N$2:$N$151,"Alto") -> 8
A17: Crítico | B17: =COUNTIF(Riesgos!$K$2:$K$151,"Crítico") -> 0 | D17: Crítico | E17: =COUNTIF(Riesgos!$N$2:$N$151,"Crítico") -> 0

Sheet Tratamiento
A1: No | B1: Activo | C1: Criticidad del Activo | D1: Riesgos Bajo | E1: Riesgos Moderado | F1: Riesgos Alto | G1: Riesgos Crítico | H1: Prioridad de Tratamiento
A2: 1 | B2: =Inventario_Activos!D2 -> Servidor de Base de Datos | C2: =Inventario_Activos!I2 -> 5 | D2: =COUNTIFS(Riesgos!$D$2:$D$151,B2,Riesgos!$K$2:$K$151,"Bajo") -> 0 | E2: =COUNTIFS(Riesgos!$D$2:$D$151,B2,Riesgos!$K$2:$K$151,"Moderado") -> 3 | F2: =COUNTIFS(Riesgos!$D$2:$D$151,B2,Riesgos!$K$2:$K$151,"Alto") -> 7 | G2: =COUNTIFS(Riesgos!$D$2:$D$151,B2,Riesgos!$K$2:$K$151,"Crítico") -> 0 | H2: =IF(G2>0,"Prioridad Muy Alta",IF(F2>0,"Prioridad Alta",IF(E2>0,"Prioridad Media","Prioridad Baja"))) -> Prioridad Alta
A3: 2 | B3: =Inventario_Activos!D3 -> Sistema ERP / Facturación | C3: =Inventario_Activos!I3 -> 3 | D3: =COUNTIFS(Riesgos!$D$2:$D$151,B3,Riesgos!$K$2:$K$151,"Bajo") -> 0 | E3: =COUNTIFS(Riesgos!$D$2:$D$151,B3,Riesgos!$K$2:$K$151,"Moderado") -> 4 | F3: =COUNTIFS(Riesgos!$D$2:$D$151,B3,Riesgos!$K$2:$K$151,"Alto") -> 6 | G3: =COUNTIFS(Riesgos!$D$2:$D$151,B3,Riesgos!$K$2:$K$151,"Crítico") -> 0 | H3: =IF(G3>0,"Prioridad Muy Alta",IF(F3>0,"Prioridad Alta",IF(E3>0,"Prioridad Media","Prioridad Baja"))) -> Prioridad Alta
A4: 3 | B4: =Inventario_Activos!D4 -> Datos de clientes | C4: =Inventario_Activos!I4 -> 3 | D4: =COUNTIFS(Riesgos!$D$2:$D$151,B4,Riesgos!$K$2:$K$151,"Bajo") -> 0 | E4: =COUNTIFS(Riesgos!$D$2:$D$151,B4,Riesgos!$K$2:$K$151,"Moderado") -> 3 | F4: =COUNTIFS(Riesgos!$D$2:$D$151,B4,Riesgos!$K$2:$K$151,"Alto") -> 7 | G4: =COUNTIFS(Riesgos!$D$2:$D$151,B4,Riesgos!$K$2:$K$151,"Crítico") -> 0 | H4: =IF(G4>0,"Prioridad Muy Alta",IF(F4>0,"Prioridad Alta",IF(E4>0,"Prioridad Media","Prioridad Baja"))) -> Prioridad Alta
A5: 4 | B5: =Inventario_Activos!D5 -> Administrador de sistemas | C5: =Inventario_Activos!I5 -> 3 | D5: =COUNTIFS(Riesgos!$D$2:$D$151,B5,Riesgos!$K$2:$K$151,"Bajo") -> 0 | E5: =COUNTIFS(Riesgos!$D$2:$D$151,B5,Riesgos!$K$2:$K$151,"Moderado") -> 3 | F5: =COUNTIFS(Riesgos!$D$2:$D$151,B5,Riesgos!$K$2:$K$151,"Alto") -> 7 | G5: =COUNTIFS(Riesgos!$D$2:$D$151,B5,Riesgos!$K$2:$K$151,"Crítico") -> 0 | H5: =IF(G5>0,"Prioridad Muy Alta",IF(F5>0,"Prioridad Alta",IF(E5>0,"Prioridad Media","Prioridad Baja"))) -> Prioridad Alta
A6: 5 | B6: =Inventario_Activos!D6 -> Firewall / Router de borde | C6: =Inventario_Activos!I6 -> 3 | D6: =COUNTIFS(Riesgos!$D$2:$D$151,B6,Riesgos!$K$2:$K$151,"Bajo") -> 0 | E6: =COUNTIFS(Riesgos!$D$2:$D$151,B6,Riesgos!$K$2:$K$151,"Moderado") -> 4 | F6: =COUNTIFS(Riesgos!$D$2:$D$151,B6,Riesgos!$K$2:$K$151,"Alto") -> 6 | G6: =COUNTIFS(Riesgos!$D$2:$D$151,B6,Riesgos!$K$2:$K$151,"Crítico") -> 0 | H6: =IF(G6>0,"Prioridad Muy Alta",IF(F6>0,"Prioridad Alta",IF(E6>0,"Prioridad Media","Prioridad Baja"))) -> Prioridad Alta
A7: 6 | B7: =Inventario_Activos!D7 -> Servidor de pruebas | C7: =Inventario_Activos!I7 -> 3 | D7: =COUNTIFS(Riesgos!$D$2:$D$151,B7,Riesgos!$K$2:$K$151,"Bajo") -> 2 | E7: =COUNTIFS(Riesgos!$D$2:$D$151,B7,Riesgos!$K$2:$K$151,"Moderado") -> 5 | F7: =COUNTIFS(Riesgos!$D$2:$D$151,B7,Riesgos!$K$2:$K$151,"Alto") -> 3 | G7: =COUNTIFS(Riesgos!$D$2:$D$151,B7,Riesgos!$K$2:$K$151,"Crítico") -> 0 | H7: =IF(G7>0,"Prioridad Muy Alta",IF(F7>0,"Prioridad Alta",IF(E7>0,"Prioridad Media","Prioridad Baja"))) -> Prioridad Alta
A8: 7 | B8: =Inventario_Activos!D8 -> Ambiente de staging web | C8: =Inventario_Activos!I8 -> 3 | D8: =COUNTIFS(Riesgos!$D$2:$D$151,B8,Riesgos!$K$2:$K$151,"Bajo") -> 2 | E8: =COUNTIFS(Riesgos!$D$2:$D$151,B8,Riesgos!$K$2:$K$151,"Moderado") -> 4 | F8: =COUNTIFS(Riesgos!$D$2:$D$151,B8,Riesgos!$K$2:$K$151,"Alto") -> 4 | G8: =COUNTIFS(Riesgos!$D$2:$D$151,B8,Riesgos!$K$2:$K$151,"Crítico") -> 0 | H8: =IF(G8>0,"Prioridad Muy Alta",IF(F8>0,"Prioridad Alta",IF(E8>0,"Prioridad Media","Prioridad Baja"))) -> Prioridad Alta
A9: 8 | B9: =Inventario_Activos!D9 -> Datos de prueba anonimizados | C9: =Inventario_Activos!I9 -> 3 | D9: =COUNTIFS(Riesgos!$D$2:$D$151,B9,Riesgos!$K$2:$K$151,"Bajo") -> 2 | E9: =COUNTIFS(Riesgos!$D$2:$D$151,B9,Riesgos!$K$2:$K$151,"Moderado") -> 6 | F9: =COUNTIFS(Riesgos!$D$2:$D$151,B9,Riesgos!$K$2:$K$151,"Alto") -> 2 | G9: =COUNTIFS(Riesgos!$D$2:$D$151,B9,Riesgos!$K$2:$K$151,"Crítico") -> 0 | H9: =IF(G9>0,"Prioridad Muy Alta",IF(F9>0,"Prioridad Alta",IF(E9>0,"Prioridad Media","Prioridad Baja"))) -> Prioridad Alta
A10: 9 | B10: =Inventario_Activos!D10 -> QA Tester | C10: =Inventario_Activos!I10 -> 3 | D10: =COUNTIFS(Riesgos!$D$2:$D$151,B10,Riesgos!$K$2:$K$151,"Bajo") -> 0 | E10: =COUNTIFS(Riesgos!$D$2:$D$151,B10,Riesgos!$K$2:$K$151,"Moderado") -> 10 | F10: =COUNTIFS(Riesgos!$D$2:$D$151,B10,Riesgos!$K$2:$K$151,"Alto") -> 0 | G10: =COUNTIFS(Riesgos!$D$2:$D$151,B10,Riesgos!$K$2:$K$151,"Crítico") -> 0 | H10: =IF(G10>0,"Prioridad Muy Alta",IF(F10>0,"Prioridad Alta",IF(E10>0,"Prioridad Media","Prioridad Baja"))) -> Prioridad Media
A11: 10 | B11: =Inventario_Activos!D11 -> Herramienta de automatización de pruebas | C11: =Inventario_Activos!I11 -> 3 | D11: =COUNTIFS(Riesgos!$D$2:$D$151,B11,Riesgos!$K$2:$K$151,"Bajo") -> 1 | E11: =COUNTIFS(Riesgos!$D$2:$D$151,B11,Riesgos!$K$2:$K$151,"Moderado") -> 6 | F11: =COUNTIFS(Riesgos!$D$2:$D$151,B11,Riesgos!$K$2:$K$151,"Alto") -> 3 | G11: =COUNTIFS(Riesgos!$D$2:$D$151,B11,Riesgos!$K$2:$K$151,"Crítico") -> 0 | H11: =IF(G11>0,"Prioridad Muy Alta",IF(F11>0,"Prioridad Alta",IF(E11>0,"Prioridad Media","Prioridad Baja"))) -> Prioridad Alta
A12: 11 | B12: =Inventario_Activos!D12 -> Estación de trabajo del desarrollador | C12: =Inventario_Activos!I12 -> 3 | D12: =COUNTIFS(Riesgos!$D$2:$D$151,B12,Riesgos!$K$2:$K$151,"Bajo") -> 0 | E12: =COUNTIFS(Riesgos!$D$2:$D$151,B12,Riesgos!$K$2:$K$151,"Moderado") -> 7 | F12: =COUNTIFS(Riesgos!$D$2:$D$151,B12,Riesgos!$K$2:$K$151,"Alto") -> 3 | G12: =COUNTIFS(Riesgos!$D$2:$D$151,B12,Riesgos!$K$2:$K$151,"Crítico") -> 0 | H12: =IF(G12>0,"Prioridad Muy Alta",IF(F12>0,"Prioridad Alta",IF(E12>0,"Prioridad Media","Prioridad Baja"))) -> Prioridad Alta
A13: 12 | B13: =Inventario_Activos!D13 -> Repositorio de código (Git) | C13: =Inventario_Activos!I13 -> 3 | D13: =COUNTIFS(Riesgos!$D$2:$D$151,B13,Riesgos!$K$2:$K$151,"Bajo") -> 0 | E13: =COUNTIFS(Riesgos!$D$2:$D$151,B13,Riesgos!$K$2:$K$151,"Moderado") -> 5 | F13: =COUNTIFS(Riesgos!$D$2:$D$151,B13,Riesgos!$K$2:$K$151,"Alto") -> 5 | G13: =COUNTIFS(Riesgos!$D$2:$D$151,B13,Riesgos!$K$2:$K$151,"Crítico") -> 0 | H13: =IF(G13>0,"Prioridad Muy Alta",IF(F13>0,"Prioridad Alta",IF(E13>0,"Prioridad Media","Prioridad Baja"))) -> Prioridad Alta
... A16: 15 | B16: =Inventario_Activos!D16 -> Entorno IDE / CI-CD | C16: =Inventario_Activos!I16 -> 3 | D16: =COUNTIFS(Riesgos!$D$2:$D$151,B16,Riesgos!$K$2:$K$151,"Bajo") -> 0 | E16: =COUNTIFS(Riesgos!$D$2:$D$151,B16,Riesgos!$K$2:$K$151,"Moderado") -> 3 | F16: =COUNTIFS(Riesgos!$D$2:$D$151,B16,Riesgos!$K$2:$K$151,"Alto") -> 7 | G16: =COUNTIFS(Riesgos!$D$2:$D$151,B16,Riesgos!$K$2:$K$151,"Crítico") -> 0 | H16: =IF(G16>0,"Prioridad Muy Alta",IF(F16>0,"Prioridad Alta",IF(E16>0,"Prioridad Media","Prioridad Baja"))) -> Prioridad Alta

Sheet Escalas
A1: Escala de Probabilidad / Impacto (1-5) | E1: Niveles de Riesgo (MAGERIT / OCTAVE)
A2: Valor | B2: Descripción | E2: Límite inferior | F2: Nivel | G2: Color
A3: 1 | B3: Muy baja | E3: 1 | F3: Bajo | G3: Verde
A4: 2 | B4: Baja | E4: 6 | F4: Moderado | G4: Amarillo
A5: 3 | B5: Media | E5: 11 | F5: Alto | G5: Naranja
A6: 4 | B6: Alta | E6: 16 | F6: Crítico | G6: Rojo
A7: 5 | B7: Muy alta
A9: Criticidad de Activos (1-5) | E9: Tratamiento de Riesgo
A10: Límite inferior | B10: Clasificación | E10: Evitar
A11: 1 | B11: Baja | E11: Reducir/Mitigar
A12: 2 | B12: Media | E12: Transferir
A13: 4 | B13: Alta | E13: Aceptar
A14: 5 | B14: Muy alta

Sheet Top10_y_Graficas
B2: TOP 10 RIESGOS MÁS CRÍTICOS Y GRÁFICAS DE RESUMEN
B3: Los 10 riesgos con mayor puntaje de Riesgo MAGERIT (Probabilidad x Impacto), calculados automáticamente desde la hoja Riesgos.
B5: Puesto | C5: Ambiente | D5: Activo | E5: Capa de Seguridad | F5: Amenaza | G5: Prob. | H5: Impacto | I5: Riesgo MAGERIT | J5: Nivel MAGERIT | K5: Riesgo OCTAVE | L5: Nivel OCTAVE | M5: Tratamiento
B6: 1 | C6: =INDEX(Riesgos!$B$2:$B$151,MATCH(LARGE(Riesgos!$Q$2:$Q$151,1),Riesgos!$Q$2:$Q$151,0)) -> Desarrollo | D6: =INDEX(Riesgos!$D$2:$D$151,MATCH(LARGE(Riesgos!$Q$2:$Q$151,1),Riesgos!$Q$2:$Q$151,0)) -> Código fuente y credenciales | E6: =INDEX(Riesgos!$E$2:$E$151,MATCH(LARGE(Riesgos!$Q$2:$Q$151,1),Riesgos!$Q$2:$Q$151,0)) -> Seguridad de Aplicación | F6: =INDEX(Riesgos!$G$2:$G$151,MATCH(LARGE(Riesgos!$Q$2:$Q$151,1),Riesgos!$Q$2:$Q$151,0)) -> Exposición de credenciales al compartir o publicar el código | G6: =INDEX(Riesgos!$H$2:$H$151,MATCH(LARGE(Riesgos!$Q$2:$Q$151,1),Riesgos!$Q$2:$Q$151,0)) -> 4 | H6: =INDEX(Riesgos!$I$2:$I$151,MATCH(LARGE(Riesgos!$Q$2:$Q$151,1),Riesgos!$Q$2:$Q$151,0)) -> 5 | I6: =INDEX(Riesgos!$J$2:$J$151,MATCH(LARGE(Riesgos!$Q$2:$Q$151,1),Riesgos!$Q$2:$Q$151,0)) -> 20 | J6: =INDEX(Riesgos!$K$2:$K$151,MATCH(LARGE(Riesgos!$Q$2:$Q$151,1),Riesgos!$Q$2:$Q$151,0)) -> Alto | K6: =INDEX(Riesgos!$M$2:$M$151,MATCH(LARGE(Riesgos!$Q$2:$Q$151,1),Riesgos!$Q$2:$Q$151,0)) -> 12 | L6: =INDEX(Riesgos!$N$2:$N$151,MATCH(LARGE(Riesgos!$Q$2:$Q$151,1),Riesgos!$Q$2:$Q$151,0)) -> Alto | M6: =INDEX(Riesgos!$O$2:$O$151,MATCH(LARGE(Riesgos!$Q$2:$Q$151,1),Riesgos!$Q$2:$Q$151,0)) -> Reducir/Mitigar
B7: 2 | C7: =INDEX(Riesgos!$B$2:$B$151,MATCH(LARGE(Riesgos!$Q$2:$Q$151,2),Riesgos!$Q$2:$Q$151,0)) -> Producción | D7: =INDEX(Riesgos!$D$2:$D$151,MATCH(LARGE(Riesgos!$Q$2:$Q$151,2),Riesgos!$Q$2:$Q$151,0)) -> Servidor de Base de Datos | E7: =INDEX(Riesgos!$E$2:$E$151,MATCH(LARGE(Riesgos!$Q$2:$Q$151,2),Riesgos!$Q$2:$Q$151,0)) -> Seguridad de Host | F7: =INDEX(Riesgos!$G$2:$G$151,MATCH(LARGE(Riesgos!$Q$2:$Q$151,2),Riesgos!$Q$2:$Q$151,0)) -> Explotación de vulnerabilidades conocidas | G7: =INDEX(Riesgos!$H$2:$H$151,MATCH(LARGE(Riesgos!$Q$2:$Q$151,2),Riesgos!$Q$2:$Q$151,0)) -> 4 | H7: =INDEX(Riesgos!$I$2:$I$151,MATCH(LARGE(Riesgos!$Q$2:$Q$151,2),Riesgos!$Q$2:$Q$151,0)) -> 4 | I7: =INDEX(Riesgos!$J$2:$J$151,MATCH(LARGE(Riesgos!$Q$2:$Q$151,2),Riesgos!$Q$2:$Q$151,0)) -> 16 | J7: =INDEX(Riesgos!$K$2:$K$151,MATCH(LARGE(Riesgos!$Q$2:$Q$151,2),Riesgos!$Q$2:$Q$151,0)) -> Alto | K7: =INDEX(Riesgos!$M$2:$M$151,MATCH(LARGE(Riesgos!$Q$2:$Q$151,2),Riesgos!$Q$2:$Q$151,0)) -> 16 | L7: =INDEX(Riesgos!$N$2:$N$151,MATCH(LARGE(Riesgos!$Q$2:$Q$151,2),Riesgos!$Q$2:$Q$151,0)) -> Alto | M7: =INDEX(Riesgos!$O$2:$O$151,MATCH(LARGE(Riesgos!$Q$2:$Q$151,2),Riesgos!$Q$2:$Q$151,0)) -> Reducir/Mitigar
B8: 3 | C8: =INDEX(Riesgos!$B$2:$B$151,MATCH(LARGE(Riesgos!$Q$2:$Q$151,3),Riesgos!$Q$2:$Q$151,0)) -> Producción | D8: =INDEX(Riesgos!$D$2:$D$151,MATCH(LARGE(Riesgos!$Q$2:$Q$151,3),Riesgos!$Q$2:$Q$151,0)) -> Servidor de Base de Datos | E8: =INDEX(Riesgos!$E$2:$E$151,MATCH(LARGE(Riesgos!$Q$2:$Q$151,3),Riesgos!$Q$2:$Q$151,0)) -> Concientización y Procesos | F8: =INDEX(Riesgos!$G$2:$G$151,MATCH(LARGE(Riesgos!$Q$2:$Q$151,3),Riesgos!$Q$2:$Q$151,0)) -> Explotación de vulnerabilidades no corregidas | G8: =INDEX(Riesgos!$H$2:$H$151,MATCH(LARGE(Riesgos!$Q$2:$Q$151,3),Riesgos!$Q$2:$Q$151,0)) -> 4 | H8: =INDEX(Riesgos!$I$2:$I$151,MATCH(LARGE(Riesgos!$Q$2:$Q$151,3),Riesgos!$Q$2:$Q$151,0)) -> 4 | I8: =INDEX(Riesgos!$J$2:$J$151,MATCH(LARGE(Riesgos!$Q$2:$Q$151,3),Riesgos!$Q$2:$Q$151,0)) -> 16 | J8: =INDEX(Riesgos!$K$2:$K$151,MATCH(LARGE(Riesgos!$Q$2:$Q$151,3),Riesgos!$Q$2:$Q$151,0)) -> Alto | K8: =INDEX(Riesgos!$M$2:$M$151,MATCH(LARGE(Riesgos!$Q$2:$Q$151,3),Riesgos!$Q$2:$Q$151,0)) -> 16 | L8: =INDEX(Riesgos!$N$2:$N$151,MATCH(LARGE(Riesgos!$Q$2:$Q$151,3),Riesgos!$Q$2:$Q$151,0)) -> Alto | M8: =INDEX(Riesgos!$O$2:$O$151,MATCH(LARGE(Riesgos!$Q$2:$Q$151,3),Riesgos!$Q$2:$Q$151,0)) -> Reducir/Mitigar
B9: 4 | C9: =INDEX(Riesgos!$B$2:$B$151,MATCH(LARGE(Riesgos!$Q$2:$Q$151,4),Riesgos!$Q$2:$Q$151,0)) -> Pruebas | D9: =INDEX(Riesgos!$D$2:$D$151,MATCH(LARGE(Riesgos!$Q$2:$Q$151,4),Riesgos!$Q$2:$Q$151,0)) -> Servidor de pruebas | E9: =INDEX(Riesgos!$E$2:$E$151,MATCH(LARGE(Riesgos!$Q$2:$Q$151,4),Riesgos!$Q$2:$Q$151,0)) -> Seguridad Perimetral | F9: =INDEX(Riesgos!$G$2:$G$151,MATCH(LARGE(Riesgos!$Q$2:$Q$151,4),Riesgos!$Q$2:$Q$151,0)) -> Ataques de fuerza bruta desde internet | G9: =INDEX(Riesgos!$H$2:$H$151,MATCH(LARGE(Riesgos!$Q$2:$Q$151,4),Riesgos!$Q$2:$Q$151,0)) -> 4 | H9: =INDEX(Riesgos!$I$2:$I$151,MATCH(LARGE(Riesgos!$Q$2:$Q$151,4),Riesgos!$Q$2:$Q$151,0)) -> 4 | I9: =INDEX(Riesgos!$J$2:$J$151,MATCH(LARGE(Riesgos!$Q$2:$Q$151,4),Riesgos!$Q$2:$Q$151,0)) -> 16 | J9: =INDEX(Riesgos!$K$2:$K$151,MATCH(LARGE(Riesgos!$Q$2:$Q$151,4),Riesgos!$Q$2:$Q$151,0)) -> Alto | K9: =INDEX(Riesgos!$M$2:$M$151,MATCH(LARGE(Riesgos!$Q$2:$Q$151,4),Riesgos!$Q$2:$Q$151,0)) -> 10 | L9: =INDEX(Riesgos!$N$2:$N$151,MATCH(LARGE(Riesgos!$Q$2:$Q$151,4),Riesgos!$Q$2:$Q$151,0)) -> Moderado | M9: =INDEX(Riesgos!$O$2:$O$151,MATCH(LARGE(Riesgos!$Q$2:$Q$151,4),Riesgos!$Q$2:$Q$151,0)) -> Reducir/Mitigar
B10: 5 | C10: =INDEX(Riesgos!$B$2:$B$151,MATCH(LARGE(Riesgos!$Q$2:$Q$151,5),Riesgos!$Q$2:$Q$151,0)) -> Pruebas | D10: =INDEX(Riesgos!$D$2:$D$151,MATCH(LARGE(Riesgos!$Q$2:$Q$151,5),Riesgos!$Q$2:$Q$151,0)) -> Herramienta de automatización de pruebas | E10: =INDEX(Riesgos!$E$2:$E$151,MATCH(LARGE(Riesgos!$Q$2:$Q$151,5),Riesgos!$Q$2:$Q$151,0)) -> Seguridad de Aplicación | F10: =INDEX(Riesgos!$G$2:$G$151,MATCH(LARGE(Riesgos!$Q$2:$Q$151,5),Riesgos!$Q$2:$Q$151,0)) -> Exposición de credenciales de otros sistemas | G10: =INDEX(Riesgos!$H$2:$H$151,MATCH(LARGE(Riesgos!$Q$2:$Q$151,5),Riesgos!$Q$2:$Q$151,0)) -> 4 | H10: =INDEX(Riesgos!$I$2:$I$151,MATCH(LARGE(Riesgos!$Q$2:$Q$151,5),Riesgos!$Q$2:$Q$151,0)) -> 4 | I10: =INDEX(Riesgos!$J$2:$J$151,MATCH(LARGE(Riesgos!$Q$2:$Q$151,5),Riesgos!$Q$2:$Q$151,0)) -> 16 | J10: =INDEX(Riesgos!$K$2:$K$151,MATCH(LARGE(Riesgos!$Q$2:$Q$151,5),Riesgos!$Q$2:$Q$151,0)) -> Alto | K10: =INDEX(Riesgos!$M$2:$M$151,MATCH(LARGE(Riesgos!$Q$2:$Q$151,5),Riesgos!$Q$2:$Q$151,0)) -> 10 | L10: =INDEX(Riesgos!$N$2:$N$151,MATCH(LARGE(Riesgos!$Q$2:$Q$151,5),Riesgos!$Q$2:$Q$151,0)) -> Moderado | M10: =INDEX(Riesgos!$O$2:$O$151,MATCH(LARGE(Riesgos!$Q$2:$Q$151,5),Riesgos!$Q$2:$Q$151,0)) -> Reducir/Mitigar
B11: 6 | C11: =INDEX(Riesgos!$B$2:$B$151,MATCH(LARGE(Riesgos!$Q$2:$Q$151,6),Riesgos!$Q$2:$Q$151,0)) -> Desarrollo | D11: =INDEX(Riesgos!$D$2:$D$151,MATCH(LARGE(Riesgos!$Q$2:$Q$151,6),Riesgos!$Q$2:$Q$151,0)) -> Código fuente y credenciales | E11: =INDEX(Riesgos!$E$2:$E$151,MATCH(LARGE(Riesgos!$Q$2:$Q$151,6),Riesgos!$Q$2:$Q$151,0)) -> Seguridad de Host | F11: =INDEX(Riesgos!$G$2:$G$151,MATCH(LARGE(Riesgos!$Q$2:$Q$151,6),Riesgos!$Q$2:$Q$151,0)) -> Robo de credenciales desde archivos locales | G11: =INDEX(Riesgos!$H$2:$H$151,MATCH(LARGE(Riesgos!$Q$2:$Q$151,6),Riesgos!$Q$2:$Q$151,0)) -> 4 | H11: =INDEX(Riesgos!$I$2:$I$151,MATCH(LARGE(Riesgos!$Q$2:$Q$151,6),Riesgos!$Q$2:$Q$151,0)) -> 4 | I11: =INDEX(Riesgos!$J$2:$J$151,MATCH(LARGE(Riesgos!$Q$2:$Q$151,6),Riesgos!$Q$2:$Q$151,0)) -> 16 | J11: =INDEX(Riesgos!$K$2:$K$151,MATCH(LARGE(Riesgos!$Q$2:$Q$151,6),Riesgos!$Q$2:$Q$151,0)) -> Alto | K11: =INDEX(Riesgos!$M$2:$M$151,MATCH(LARGE(Riesgos!$Q$2:$Q$151,6),Riesgos!$Q$2:$Q$151,0)) -> 10 | L11: =INDEX(Riesgos!$N$2:$N$151,MATCH(LARGE(Riesgos!$Q$2:$Q$151,6),Riesgos!$Q$2:$Q$151,0)) -> Moderado | M11: =INDEX(Riesgos!$O$2:$O$151,MATCH(LARGE(Riesgos!$Q$2:$Q$151,6),Riesgos!$Q$2:$Q$151,0)) -> Reducir/Mitigar
B12: 7 | C12: =INDEX(Riesgos!$B$2:$B$151,MATCH(LARGE(Riesgos!$Q$2:$Q$151,7),Riesgos!$Q$2:$Q$151,0)) -> Desarrollo | D12: =INDEX(Riesgos!$D$2:$D$151,MATCH(LARGE(Riesgos!$Q$2:$Q$151,7),Riesgos!$Q$2:$Q$151,0)) -> Desarrollador | E12: =INDEX(Riesgos!$E$2:$E$151,MATCH(LARGE(Riesgos!$Q$2:$Q$151,7),Riesgos!$Q$2:$Q$151,0)) -> Seguridad de Aplicación | F12: =INDEX(Riesgos!$G$2:$G$151,MATCH(LARGE(Riesgos!$Q$2:$Q$151,7),Riesgos!$Q$2:$Q$151,0)) -> Introducción de vulnerabilidades en el software desarrollado | G12: =INDEX(Riesgos!$H$2:$H$151,MATCH(LARGE(Riesgos!$Q$2:$Q$151,7),Riesgos!$Q$2:$Q$151,0)) -> 4 | H12: =INDEX(Riesgos!$I$2:$I$151,MATCH(LARGE(Riesgos!$Q$2:$Q$151,7),Riesgos!$Q$2:$Q$151,0)) -> 4 | I12: =INDEX(Riesgos!$J$2:$J$151,MATCH(LARGE(Riesgos!$Q$2:$Q$151,7),Riesgos!$Q$2:$Q$151,0)) -> 16 | J12: =INDEX(Riesgos!$K$2:$K$151,MATCH(LARGE(Riesgos!$Q$2:$Q$151,7),Riesgos!$Q$2:$Q$151,0)) -> Alto | K12: =INDEX(Riesgos!$M$2:$M$151,MATCH(LARGE(Riesgos!$Q$2:$Q$151,7),Riesgos!$Q$2:$Q$151,0)) -> 10 | L12: =INDEX(Riesgos!$N$2:$N$151,MATCH(LARGE(Riesgos!$Q$2:$Q$151,7),Riesgos!$Q$2:$Q$151,0)) -> Moderado | M12: =INDEX(Riesgos!$O$2:$O$151,MATCH(LARGE(Riesgos!$Q$2:$Q$151,7),Riesgos!$Q$2:$Q$151,0)) -> Reducir/Mitigar
B13: 8 | C13: =INDEX(Riesgos!$B$2:$B$151,MATCH(LARGE(Riesgos!$Q$2:$Q$151,8),Riesgos!$Q$2:$Q$151,0)) -> Producción | D13: =INDEX(Riesgos!$D$2:$D$151,MATCH(LARGE(Riesgos!$Q$2:$Q$151,8),Riesgos!$Q$2:$Q$151,0)) -> Servidor de Base de Datos | E13: =INDEX(Riesgos!$E$2:$E$151,MATCH(LARGE(Riesgos!$Q$2:$Q$151,8),Riesgos!$Q$2:$Q$151,0)) -> Seguridad de Red | F13: =INDEX(Riesgos!$G$2:$G$151,MATCH(LARGE(Riesgos!$Q$2:$Q$151,8),Riesgos!$Q$2:$Q$151,0)) -> Acceso remoto no autorizado | G13: =INDEX(Riesgos!$H$2:$H$151,MATCH(LARGE(Riesgos!$Q$2:$Q$151,8),Riesgos!$Q$2:$Q$151,0)) -> 3 | H13: =INDEX(Riesgos!$I$2:$I$151,MATCH(LARGE(Riesgos!$Q$2:$Q$151,8),Riesgos!$Q$2:$Q$151,0)) -> 5 | I13: =INDEX(Riesgos!$J$2:$J$151,MATCH(LARGE(Riesgos!$Q$2:$Q$151,8),Riesgos!$Q$2:$Q$151,0)) -> 15 | J13: =INDEX(Riesgos!$K$2:$K$151,MATCH(LARGE(Riesgos!$Q$2:$Q$151,8),Riesgos!$Q$2:$Q$151,0)) -> Alto | K13: =INDEX(Riesgos!$M$2:$M$151,MATCH(LARGE(Riesgos!$Q$2:$Q$151,8),Riesgos!$Q$2:$Q$151,0)) -> 15 | L13: =INDEX(Riesgos!$N$2:$N$151,MATCH(LARGE(Riesgos!$Q$2:$Q$151,8),Riesgos!$Q$2:$Q$151,0)) -> Alto | M13: =INDEX(Riesgos!$O$2:$O$151,MATCH(LARGE(Riesgos!$Q$2:$Q$151,8),Riesgos!$Q$2:$Q$151,0)) -> Reducir/Mitigar
B14: 9 | C14: =INDEX(Riesgos!$B$2:$B$151,MATCH(LARGE(Riesgos!$Q$2:$Q$151,9),Riesgos!$Q$2:$Q$151,0)) -> Producción | D14: =INDEX(Riesgos!$D$2:$D$151,MATCH(LARGE(Riesgos!$Q$2:$Q$151,9),Riesgos!$Q$2:$Q$151,0)) -> Servidor de Base de Datos | E14: =INDEX(Riesgos!$E$2:$E$151,MATCH(LARGE(Riesgos!$Q$2:$Q$151,9),Riesgos!$Q$2:$Q$151,0)) -> Seguridad de Aplicación | F14: =INDEX(Riesgos!$G$2:$G$151,MATCH(LARGE(Riesgos!$Q$2:$Q$151,9),Riesgos!$Q$2:$Q$151,0)) -> Inyección SQL / escalamiento de privilegios | G14: =INDEX(Riesgos!$H$2:$H$151,MATCH(LARGE(Riesgos!$Q$2:$Q$151,9),Riesgos!$Q$2:$Q$151,0)) -> 3 | H14: =INDEX(Riesgos!$I$2:$I$151,MATCH(LARGE(Riesgos!$Q$2:$Q$151,9),Riesgos!$Q$2:$Q$151,0)) -> 5 | I14: =INDEX(Riesgos!$J$2:$J$151,MATCH(LARGE(Riesgos!$Q$2:$Q$151,9),Riesgos!$Q$2:$Q$151,0)) -> 15 | J14: =INDEX(Riesgos!$K$2:$K$151,MATCH(LARGE(Riesgos!$Q$2:$Q$151,9),Riesgos!$Q$2:$Q$151,0)) -> Alto | K14: =INDEX(Riesgos!$M$2:$M$151,MATCH(LARGE(Riesgos!$Q$2:$Q$151,9),Riesgos!$Q$2:$Q$151,0)) -> 15 | L14: =INDEX(Riesgos!$N$2:$N$151,MATCH(LARGE(Riesgos!$Q$2:$Q$151,9),Riesgos!$Q$2:$Q$151,0)) -> Alto | M14: =INDEX(Riesgos!$O$2:$O$151,MATCH(LARGE(Riesgos!$Q$2:$Q$151,9),Riesgos!$Q$2:$Q$151,0)) -> Reducir/Mitigar
B15: 10 | C15: =INDEX(Riesgos!$B$2:$B$151,MATCH(LARGE(Riesgos!$Q$2:$Q$151,10),Riesgos!$Q$2:$Q$151,0)) -> Producción | D15: =INDEX(Riesgos!$D$2:$D$151,MATCH(LARGE(Riesgos!$Q$2:$Q$151,10),Riesgos!$Q$2:$Q$151,0)) -> Servidor de Base de Datos | E15: =INDEX(Riesgos!$E$2:$E$151,MATCH(LARGE(Riesgos!$Q$2:$Q$151,10),Riesgos!$Q$2:$Q$151,0)) -> Seguridad de Datos | F15: =INDEX(Riesgos!$G$2:$G$151,MATCH(LARGE(Riesgos!$Q$2:$Q$151,10),Riesgos!$Q$2:$Q$151,0)) -> Fuga de información confidencial | G15: =INDEX(Riesgos!$H$2:$H$151,MATCH(LARGE(Riesgos!$Q$2:$Q$151,10),Riesgos!$Q$2:$Q$151,0)) -> 3 | H15: =INDEX(Riesgos!$I$2:$I$151,MATCH(LARGE(Riesgos!$Q$2:$Q$151,10),Riesgos!$Q$2:$Q$151,0)) -> 5 | I15: =INDEX(Riesgos!$J$2:$J$151,MATCH(LARGE(Riesgos!$Q$2:$Q$151,10),Riesgos!$Q$2:$Q$151,0)) -> 15 | J15: =INDEX(Riesgos!$K$2:$K$151,MATCH(LARGE(Riesgos!$Q$2:$Q$151,10),Riesgos!$Q$2:$Q$151,0)) -> Alto | K15: =INDEX(Riesgos!$M$2:$M$151,MATCH(LARGE(Riesgos!$Q$2:$Q$151,10),Riesgos!$Q$2:$Q$151,0)) -> 15 | L15: =INDEX(Riesgos!$N$2:$N$151,MATCH(LARGE(Riesgos!$Q$2:$Q$151,10),Riesgos!$Q$2:$Q$151,0)) -> Alto | M15: =INDEX(Riesgos!$O$2:$O$151,MATCH(LARGE(Riesgos!$Q$2:$Q$151,10),Riesgos!$Q$2:$Q$151,0)) -> Reducir/Mitigar
